Workbook

Sheet COVER

Sheet Instructions
B6: 1. | C6: La pestaña de color gris, corresponde a los precios de tarifa confidencial del catálogo ROLY 2024. The grey tab corresponds to prices in Confidential Price list for ROLY 2024 catalogue. L’onglet gris correspond aux prix du tarif confidentiel du catalogue ROLY 2024.
B7: 2. | C7: La pestaña de color verde alberga la tarifa de venta al público (PVP) recomendada para el catálogo ROLY 2024. The green tab has the recommended retail price (RRP) for ROLY 2023 catalogue. L’onglet vert contient le tarif de vente public (PVP) recommandé pour le catalogue ROLY 2024.
B8: 3. | C8: La tarifa de venta al público (PVP) puede ser editada. Para ello, sólo debe modificar el porcentaje de incremento de comercialización de la casilla bajo estas líneas: The recommended retail price (RRP) can be edited. To do this, simply modify the percentage increase of merchandising in the box under these lines: Le tarif de vente public (PVP) est éditable. Il suffit de modifier le pourcentage de la hausse des prix de commercialisation situé dans la case en dessous de ces lignes:
F9: PORCENTAJE DE INCREMENTO DE COMERCIALIZACIÓN INCREASE PERCENTAGE OF MERCHANDISING POURCENTAJE DE HAUSSE DES PRIX DE COMMERCIALISATION | AA9: 1
B13: 4. | C13: Los precios de tarifa de venta al público (PVP) no incluyen impuestos, se muestran en Euros y están redondeados al alza con dos decimales. Prices of recommended retail price (RRP) do not include taxes, they are shown in Euros and are rounded to two decimals. Les prix du tarif de vente public (PVP) n’incluent pas les impôts, se montrent en Euros et sont arrondis a deux décimaux.

Sheet Tarifa 2026
A1: TARIFA CONFIDENCIAL · CONFIDENTIAL PRICE LIST · TARIF CONFIDENTIEL
H2: PACKAGING | J2: TARIFA CONFIDENCIAL CONFIDENTIAL PRICE TARIF CONFIDENTIAL
A3: Pág. | B3: Link | C3: Ref. | D3: Nombre | E3: Género | F3: Talla | G3: Color | H3: Ud/Caja | I3: Ud/Pack | J3: Caja | K3: Pack | L3: Unid.
A4: Page | B4: Link | C4: Ref. | D4: Name | E4: Gender | F4: Size | G4: Colour | H4: Units/box | I4: Units/pack | J4: Box | K4: Pack | L4: Unit
A5: Page | B5: Link | C5: Ref. | D5: Nom | E5: Genre | F5: Taille | G5: Couleur | H5: Unité/carton | I5: Unité/blister | J5: Carton | K5: Blister | L5: Unité
A6: FOOTWEAR
A7: 12 | B7: NEW | C7: 8397 | D7: Beryl | E7: Unisex - Unisex - Unisex | F7: 34-50 | G7: Color - Colour - Couleur | H7: 10 | I7: 1 | J7: 30.9 | K7: =IF(I7=1,(ROUNDUP((J7*0.05+J7),3)),ROUNDUP((J7*0.05+J7),3)) -> 32.445 | L7: =IF(I7=1,"-",IF(AND(I7="",L11="-"),"-",ROUNDUP((J7*0.2)+J7,3))) -> -
A8: 14 | B8: NEW | C8: 8392 | D8: Onyx | E8: Unisex - Unisex - Unisex | F8: 34-50 | G8: Color - Colour - Couleur | H8: 10 | I8: 1 | J8: 24.5 | K8: =IF(I8=1,(ROUNDUP((J8*0.05+J8),3)),ROUNDUP((J8*0.05+J8),3)) -> 25.725 | L8: =IF(I8=1,"-",IF(AND(I8="",L12="-"),"-",ROUNDUP((J8*0.2)+J8,3))) -> -
A9: 16 | B9: See photo | C9: 8385 | D9: Vitinja | E9: Unisex - Unisex - Unisex | F9: 36-48 | G9: Color - Colour - Couleur | H9: 10 | I9: 1 | J9: 37.25 | K9: =IF(I9=1,(ROUNDUP((J9*0.05+J9),3)),ROUNDUP((J9*0.05+J9),3)) -> 39.113 | L9: =IF(I9=1,"-",IF(AND(I9="",L13="-"),"-",ROUNDUP((J9*0.2)+J9,3))) -> -
A10: 18 | B10: NEW | C10: 8395 | D10: Ruby | E10: Unisex - Unisex - Unisex | F10: 34-50 | G10: Color - Colour - Couleur | H10: 10 | I10: 1 | J10: 26.5 | K10: =IF(I10=1,(ROUNDUP((J10*0.05+J10),3)),ROUNDUP((J10*0.05+J10),3)) -> 27.825 | L10: =IF(I10=1,"-",IF(AND(I10="",L14="-"),"-",ROUNDUP((J10*0.2)+J10,3))) -> -
A11: 18 | B11: NEW | C11: 8394 | D11: Garnet | E11: Unisex - Unisex - Unisex | F11: 34-50 | G11: Color - Colour - Couleur | H11: 10 | I11: 1 | J11: 27.25 | K11: =IF(I11=1,(ROUNDUP((J11*0.05+J11),3)),ROUNDUP((J11*0.05+J11),3)) -> 28.613 | L11: =IF(I11=1,"-",IF(AND(I11="",L15="-"),"-",ROUNDUP((J11*0.2)+J11,3))) -> -
A12: 20 | B12: See photo | C12: 8382 | D12: Ulmus | E12: Unisex - Unisex - Unisex | F12: 36-48 | G12: Color - Colour - Couleur | H12: 10 | I12: 1 | J12: 27.3 | K12: =IF(I12=1,(ROUNDUP((J12*0.05+J12),3)),ROUNDUP((J12*0.05+J12),3)) -> 28.665 | L12: =IF(I12=1,"-",IF(AND(I12="",L14="-"),"-",ROUNDUP((J12*0.2)+J12,3))) -> -
A13: 22 | B13: See photo | C13: 8383 | D13: Ceryson | E13: Unisex - Unisex - Unisex | F13: 36-48 | G13: Color - Colour - Couleur | H13: 10 | I13: 1 | J13: 28.25 | K13: =IF(I13=1,(ROUNDUP((J13*0.05+J13),3)),ROUNDUP((J13*0.05+J13),3)) -> 29.663 | L13: =IF(I13=1,"-",IF(AND(I13="",L15="-"),"-",ROUNDUP((J13*0.2)+J13,3))) -> -
A14: 24 | B14: See photo | C14: 8380 | D14: Kercus | E14: Unisex - Unisex - Unisex | F14: 36-48 | G14: Color - Colour - Couleur | H14: 10 | I14: 1 | J14: 30.35 | K14: =IF(I14=1,(ROUNDUP((J14*0.05+J14),3)),ROUNDUP((J14*0.05+J14),3)) -> 31.868 | L14: =IF(I14=1,"-",IF(AND(I14="",L5="-"),"-",ROUNDUP((J14*0.2)+J14,3))) -> -
A15: 26 | B15: See photo | C15: 8381 | D15: Giskan | E15: Unisex - Unisex - Unisex | F15: 36-48 | G15: Color - Colour - Couleur | H15: 10 | I15: 1 | J15: 31.15 | K15: =IF(I15=1,(ROUNDUP((J15*0.05+J15),3)),ROUNDUP((J15*0.05+J15),3)) -> 32.708 | L15: =IF(I15=1,"-",IF(AND(I15="",L6="-"),"-",ROUNDUP((J15*0.2)+J15,3))) -> -
A16: 28 | B16: See photo | C16: 8384 | D16: Noboa | E16: Unisex - Unisex - Unisex | F16: 36-48 | G16: Color - Colour - Couleur | H16: 10 | I16: 1 | J16: 30.1 | K16: =IF(I16=1,(ROUNDUP((J16*0.05+J16),3)),ROUNDUP((J16*0.05+J16),3)) -> 31.605 | L16: =IF(I16=1,"-",IF(AND(I16="",L12="-"),"-",ROUNDUP((J16*0.2)+J16,3))) -> -
A17: 30 | B17: NEW | C17: 8388 | D17: Brax | E17: Unisex - Unisex - Unisex | F17: 35-50 | G17: Color - Colour - Couleur | H17: 10 | I17: 1 | J17: 20.25 | K17: =IF(I17=1,(ROUNDUP((J17*0.05+J17),3)),ROUNDUP((J17*0.05+J17),3)) -> 21.263 | L17: =IF(I17=1,"-",IF(AND(I17="",L13="-"),"-",ROUNDUP((J17*0.2)+J17,3))) -> -
A18: 32 | B18: NEW | C18: 8389 | D18: Iron | E18: Unisex - Unisex - Unisex | F18: 35-50 | G18: Color - Colour - Couleur | H18: 10 | I18: 1 | J18: 21.5 | K18: =IF(I18=1,(ROUNDUP((J18*0.05+J18),3)),ROUNDUP((J18*0.05+J18),3)) -> 22.575 | L18: =IF(I18=1,"-",IF(AND(I18="",L14="-"),"-",ROUNDUP((J18*0.2)+J18,3))) -> -
A19: 34 | B19: NEW | C19: 8390 | D19: Rock | E19: Unisex - Unisex - Unisex | F19: 35-50 | G19: Color - Colour - Couleur | H19: 10 | I19: 1 | J19: 36.5 | K19: =IF(I19=1,(ROUNDUP((J19*0.05+J19),3)),ROUNDUP((J19*0.05+J19),3)) -> 38.325 | L19: =IF(I19=1,"-",IF(AND(I19="",L15="-"),"-",ROUNDUP((J19*0.2)+J19,3))) -> -
A20: 36 | B20: NEW | C20: 8391 | D20: Lua | E20: Unisex - Unisex - Unisex | F20: 35-50 | G20: Color - Colour - Couleur | H20: 10 | I20: 1 | J20: 37.5 | K20: =IF(I20=1,(ROUNDUP((J20*0.05+J20),3)),ROUNDUP((J20*0.05+J20),3)) -> 39.375 | L20: =IF(I20=1,"-",IF(AND(I20="",L16="-"),"-",ROUNDUP((J20*0.2)+J20,3))) -> -
A21: 38 | B21: NEW | C21: 8387 | D21: Pearl | E21: Unisex - Unisex - Unisex | F21: 35-50 | G21: Color - Colour - Couleur | H21: 10 | I21: 1 | J21: 25 | K21: =IF(I21=1,(ROUNDUP((J21*0.05+J21),3)),ROUNDUP((J21*0.05+J21),3)) -> 26.25 | L21: =IF(I21=1,"-",IF(AND(I21="",L17="-"),"-",ROUNDUP((J21*0.2)+J21,3))) -> -
A22: 40 | B22: NEW | C22: 8386 | D22: Salt | E22: Unisex - Unisex - Unisex | F22: 35-50 | G22: Color - Colour - Couleur | H22: 10 | I22: 1 | J22: 21.9 | K22: =IF(I22=1,(ROUNDUP((J22*0.05+J22),3)),ROUNDUP((J22*0.05+J22),3)) -> 22.995 | L22: =IF(I22=1,"-",IF(AND(I22="",L18="-"),"-",ROUNDUP((J22*0.2)+J22,3))) -> -
A23: 41 | B23: NEW | C23: 8393 | D23: Opal | E23: Unisex - Unisex - Unisex | F23: 35-48 | G23: Color - Colour - Couleur | H23: 10 | I23: 1 | J23: 13.5 | K23: =IF(I23=1,(ROUNDUP((J23*0.05+J23),3)),ROUNDUP((J23*0.05+J23),3)) -> 14.175 | L23: =IF(I23=1,"-",IF(AND(I23="",L19="-"),"-",ROUNDUP((J23*0.2)+J23,3))) -> -
A24: 42 | B24: NEW | C24: 8396 | D24: Basalt | E24: Unisex - Unisex - Unisex | F24: 34-50 | G24: Color - Colour - Couleur | H24: 10 | I24: 1 | J24: 31.5 | K24: =IF(I24=1,(ROUNDUP((J24*0.05+J24),3)),ROUNDUP((J24*0.05+J24),3)) -> 33.075 | L24: =IF(I24=1,"-",IF(AND(I24="",L20="-"),"-",ROUNDUP((J24*0.2)+J24,3))) -> -
A25: ALTA VISIBILIDAD · HI-VIZ · HAUTE VISIBILITÉ
A26: 49 | B26: NEW | C26: 9324 | D26: Foran | E26: Unisex - Unisex - Unisex | F26: XS-2XL | G26: Color - Colour - Couleur | H26: 50 | I26: 1 | J26: 7.95 | K26: =IF(I26=1,(ROUNDUP((J26*0.05+J26),3)),ROUNDUP((J26*0.05+J26),3)) -> 8.348 | L26: =IF(I26=1,"-",IF(AND(I26="",L15="-"),"-",ROUNDUP((J26*0.2)+J26,3))) -> -
E27: Unisex - Unisex - Unisex | F27: 3XL | G27: Color - Colour - Couleur | J27: 8.35 | K27: =IF(I27=1,(ROUNDUP((J27*0.05+J27),3)),ROUNDUP((J27*0.05+J27),3)) -> 8.768 | L27: =IF(I27=1,"-",IF(AND(I27="",L12="-"),"-",ROUNDUP((J27*0.2)+J27,3))) -> -
A28: 49 | B28: NEW | C28: 9325 | D28: Foran L/S | E28: Unisex - Unisex - Unisex | F28: XS-2XL | G28: Color - Colour - Couleur | H28: 25 | I28: 1 | J28: 9.95 | K28: =IF(I28=1,(ROUNDUP((J28*0.05+J28),3)),ROUNDUP((J28*0.05+J28),3)) -> 10.448 | L28: =IF(I28=1,"-",IF(AND(I28="",L13="-"),"-",ROUNDUP((J28*0.2)+J28,3))) -> -
E29: Unisex - Unisex - Unisex | F29: 3XL | G29: Color - Colour - Couleur | J29: 10.5 | K29: =IF(I29=1,(ROUNDUP((J29*0.05+J29),3)),ROUNDUP((J29*0.05+J29),3)) -> 11.025 | L29: =IF(I29=1,"-",IF(AND(I29="",L16="-"),"-",ROUNDUP((J29*0.2)+J29,3))) -> -
A30: 50 | B30: See photo | C30: 9317 | D30: Tauri | E30: Unisex - Unisex - Unisex | F30: S-2XL | G30: Color - Colour - Couleur | H30: 50 | I30: 1 | J30: 8.95 | K30: =IF(I30=1,(ROUNDUP((J30*0.05+J30),3)),ROUNDUP((J30*0.05+J30),3)) -> 9.398 | L30: =IF(I30=1,"-",IF(AND(I30="",L9="-"),"-",ROUNDUP((J30*0.2)+J30,3))) -> -
E31: Unisex - Unisex - Unisex | F31: 3XL | G31: Color - Colour - Couleur | J31: 9.75 | K31: =IF(I31=1,(ROUNDUP((J31*0.05+J31),3)),ROUNDUP((J31*0.05+J31),3)) -> 10.238 | L31: =IF(I30=1,"-",IF(AND(I30="",L25="-"),"-",ROUNDUP((J31*0.2)+J31,3))) -> -
E32: Unisex - Unisex - Unisex | F32: 4XL | G32: Color - Colour - Couleur | J32: 10 | K32: =IF(I32=1,(ROUNDUP((J32*0.05+J32),3)),ROUNDUP((J32*0.05+J32),3)) -> 10.5 | L32: =IF(I32=1,"-",IF(AND(I32="",L30="-"),"-",ROUNDUP((J32*0.2)+J32,3))) -> -
A33: 50 | B33: See photo | C33: 9318 | D33: Atrio | E33: Unisex - Unisex - Unisex | F33: S-2XL | G33: Color - Colour - Couleur | H33: 50 | I33: 1 | J33: 9.95 | K33: =IF(I33=1,(ROUNDUP((J33*0.05+J33),3)),ROUNDUP((J33*0.05+J33),3)) -> 10.448 | L33: =IF(I33=1,"-",IF(AND(I33="",L31="-"),"-",ROUNDUP((J33*0.2)+J33,3))) -> -
E34: Unisex - Unisex - Unisex | F34: 3XL | G34: Color - Colour - Couleur | J34: 10.5 | K34: =IF(I34=1,(ROUNDUP((J34*0.05+J34),3)),ROUNDUP((J34*0.05+J34),3)) -> 11.025 | L34: =IF(I34=1,"-",IF(AND(I34="",L32="-"),"-",ROUNDUP((J34*0.2)+J34,3))) -> -
E35: Unisex - Unisex - Unisex | F35: 4XL | G35: Color - Colour - Couleur | J35: 11 | K35: =IF(I35=1,(ROUNDUP((J35*0.05+J35),3)),ROUNDUP((J35*0.05+J35),3)) -> 11.55 | L35: =IF(I35=1,"-",IF(AND(I35="",L33="-"),"-",ROUNDUP((J35*0.2)+J35,3))) -> -
A36: 51 | B36: See photo | C36: 9319 | D36: Atrio L/S | E36: Unisex - Unisex - Unisex | F36: S-2XL | G36: Color - Colour - Couleur | H36: 50 | I36: 1 | J36: 12.5 | K36: =IF(I36=1,(ROUNDUP((J36*0.05+J36),3)),ROUNDUP((J36*0.05+J36),3)) -> 13.125 | L36: =IF(I36=1,"-",IF(AND(I36="",L34="-"),"-",ROUNDUP((J36*0.2)+J36,3))) -> -
E37: Unisex - Unisex - Unisex | F37: 3XL | G37: Color - Colour - Couleur | J37: 13.15 | K37: =IF(I37=1,(ROUNDUP((J37*0.05+J37),3)),ROUNDUP((J37*0.05+J37),3)) -> 13.808 | L37: =IF(I37=1,"-",IF(AND(I37="",L35="-"),"-",ROUNDUP((J37*0.2)+J37,3))) -> -
E38: Unisex - Unisex - Unisex | F38: 4XL | G38: Color - Colour - Couleur | J38: 13.8 | K38: =IF(I38=1,(ROUNDUP((J38*0.05+J38),3)),ROUNDUP((J38*0.05+J38),3)) -> 14.49 | L38: =IF(I38=1,"-",IF(AND(I38="",L36="-"),"-",ROUNDUP((J38*0.2)+J38,3))) -> -
A39: 52 | B39: See photo | C39: 9315 | D39: Vega | E39: Unisex - Unisex - Unisex | F39: S-2XL | G39: Color - Colour - Couleur | H39: 50 | I39: 1 | J39: 6.5 | K39: =IF(I39=1,(ROUNDUP((J39*0.05+J39),3)),ROUNDUP((J39*0.05+J39),3)) -> 6.825 | L39: =IF(I39=1,"-",IF(AND(I39="",L37="-"),"-",ROUNDUP((J39*0.2)+J39,3))) -> -
E40: Unisex - Unisex - Unisex | F40: 3XL | G40: Color - Colour - Couleur | J40: 6.9 | K40: =IF(I40=1,(ROUNDUP((J40*0.05+J40),3)),ROUNDUP((J40*0.05+J40),3)) -> 7.245 | L40: =IF(I40=1,"-",IF(AND(I40="",L38="-"),"-",ROUNDUP((J40*0.2)+J40,3))) -> -
...

Sheet PVP 2026
A1: TARIFA PVP · PVP PRICE LIST · TARIF PVP
A2: Pág. | B2: Link | C2: Ref. | D2: Nombre | E2: Género | F2: Talla | G2: Color | H2: Ud/Caja | I2: Ud/Pack | J2: Caja | K2: Pack | L2: Unid.
A3: Page | B3: Link | C3: Ref. | D3: Name | E3: Gender | F3: Size | G3: Colour | H3: Units/box | I3: Units/pack | J3: Box | K3: Pack | L3: Unit
A4: Page | B4: Link | C4: Ref. | D4: Nom | E4: Genre | F4: Taille | G4: Couleur | H4: Unité/carton | I4: Unité/blister | J4: Carton | K4: Blister | L4: Unité
A5: FOOTWEAR
A6: 12 | B6: NEW | C6: 8397 | D6: Beryl | E6: Unisex - Unisex - Unisex | F6: 34-50 | G6: Color - Colour - Couleur | H6: 10 | I6: 1 | J6: =ROUNDUP('Tarifa 2026'!J7*(1+Instructions!$AA$9),3) -> 61.8 | K6: =IF(I6=1,(ROUNDUP((J6*0.05+J6),3)),ROUNDUP((J6*0.05+J6),3)) -> 64.89 | L6: =IF(I6=1,"-",IF(AND(I6="",L4="-"),"-",ROUNDUP((J6*0.2)+J6,3))) -> -
A7: 14 | B7: NEW | C7: 8392 | D7: Onyx | E7: Unisex - Unisex - Unisex | F7: 34-50 | G7: Color - Colour - Couleur | H7: 10 | I7: 1 | J7: =ROUNDUP('Tarifa 2026'!J8*(1+Instructions!$AA$9),3) -> 49 | K7: =IF(I7=1,(ROUNDUP((J7*0.05+J7),3)),ROUNDUP((J7*0.05+J7),3)) -> 51.45 | L7: =IF(I7=1,"-",IF(AND(I7="",L5="-"),"-",ROUNDUP((J7*0.2)+J7,3))) -> -
A8: 16 | B8: See photo | C8: 8385 | D8: Vitinja | E8: Unisex - Unisex - Unisex | F8: 36-48 | G8: Color - Colour - Couleur | H8: 10 | I8: 1 | J8: =ROUNDUP('Tarifa 2026'!J9*(1+Instructions!$AA$9),3) -> 74.5 | K8: =IF(I8=1,(ROUNDUP((J8*0.05+J8),3)),ROUNDUP((J8*0.05+J8),3)) -> 78.225 | L8: =IF(I8=1,"-",IF(AND(I8="",L6="-"),"-",ROUNDUP((J8*0.2)+J8,3))) -> -
A9: 18 | B9: NEW | C9: 8395 | D9: Ruby | E9: Unisex - Unisex - Unisex | F9: 34-50 | G9: Color - Colour - Couleur | H9: 10 | I9: 1 | J9: =ROUNDUP('Tarifa 2026'!J10*(1+Instructions!$AA$9),3) -> 53 | K9: =IF(I9=1,(ROUNDUP((J9*0.05+J9),3)),ROUNDUP((J9*0.05+J9),3)) -> 55.65 | L9: =IF(I9=1,"-",IF(AND(I9="",L7="-"),"-",ROUNDUP((J9*0.2)+J9,3))) -> -
A10: 18 | B10: NEW | C10: 8394 | D10: Garnet | E10: Unisex - Unisex - Unisex | F10: 34-50 | G10: Color - Colour - Couleur | H10: 10 | I10: 1 | J10: =ROUNDUP('Tarifa 2026'!J11*(1+Instructions!$AA$9),3) -> 54.5 | K10: =IF(I10=1,(ROUNDUP((J10*0.05+J10),3)),ROUNDUP((J10*0.05+J10),3)) -> 57.225 | L10: =IF(I10=1,"-",IF(AND(I10="",L8="-"),"-",ROUNDUP((J10*0.2)+J10,3))) -> -
A11: 20 | B11: See photo | C11: 8382 | D11: Ulmus | E11: Unisex - Unisex - Unisex | F11: 36-48 | G11: Color - Colour - Couleur | H11: 10 | I11: 1 | J11: =ROUNDUP('Tarifa 2026'!J12*(1+Instructions!$AA$9),3) -> 54.6 | K11: =IF(I11=1,(ROUNDUP((J11*0.05+J11),3)),ROUNDUP((J11*0.05+J11),3)) -> 57.33 | L11: =IF(I11=1,"-",IF(AND(I11="",L9="-"),"-",ROUNDUP((J11*0.2)+J11,3))) -> -
A12: 22 | B12: See photo | C12: 8383 | D12: Ceryson | E12: Unisex - Unisex - Unisex | F12: 36-48 | G12: Color - Colour - Couleur | H12: 10 | I12: 1 | J12: =ROUNDUP('Tarifa 2026'!J13*(1+Instructions!$AA$9),3) -> 56.5 | K12: =IF(I12=1,(ROUNDUP((J12*0.05+J12),3)),ROUNDUP((J12*0.05+J12),3)) -> 59.325 | L12: =IF(I12=1,"-",IF(AND(I12="",L10="-"),"-",ROUNDUP((J12*0.2)+J12,3))) -> -
A13: 24 | B13: See photo | C13: 8380 | D13: Kercus | E13: Unisex - Unisex - Unisex | F13: 36-48 | G13: Color - Colour - Couleur | H13: 10 | I13: 1 | J13: =ROUNDUP('Tarifa 2026'!J14*(1+Instructions!$AA$9),3) -> 60.7 | K13: =IF(I13=1,(ROUNDUP((J13*0.05+J13),3)),ROUNDUP((J13*0.05+J13),3)) -> 63.735 | L13: =IF(I13=1,"-",IF(AND(I13="",L11="-"),"-",ROUNDUP((J13*0.2)+J13,3))) -> -
A14: 26 | B14: See photo | C14: 8381 | D14: Giskan | E14: Unisex - Unisex - Unisex | F14: 36-48 | G14: Color - Colour - Couleur | H14: 10 | I14: 1 | J14: =ROUNDUP('Tarifa 2026'!J15*(1+Instructions!$AA$9),3) -> 62.3 | K14: =IF(I14=1,(ROUNDUP((J14*0.05+J14),3)),ROUNDUP((J14*0.05+J14),3)) -> 65.415 | L14: =IF(I14=1,"-",IF(AND(I14="",L12="-"),"-",ROUNDUP((J14*0.2)+J14,3))) -> -
A15: 28 | B15: See photo | C15: 8384 | D15: Noboa | E15: Unisex - Unisex - Unisex | F15: 36-48 | G15: Color - Colour - Couleur | H15: 10 | I15: 1 | J15: =ROUNDUP('Tarifa 2026'!J16*(1+Instructions!$AA$9),3) -> 60.2 | K15: =IF(I15=1,(ROUNDUP((J15*0.05+J15),3)),ROUNDUP((J15*0.05+J15),3)) -> 63.21 | L15: =IF(I15=1,"-",IF(AND(I15="",L13="-"),"-",ROUNDUP((J15*0.2)+J15,3))) -> -
A16: 30 | B16: NEW | C16: 8388 | D16: Brax | E16: Unisex - Unisex - Unisex | F16: 35-50 | G16: Color - Colour - Couleur | H16: 10 | I16: 1 | J16: =ROUNDUP('Tarifa 2026'!J17*(1+Instructions!$AA$9),3) -> 40.5 | K16: =IF(I16=1,(ROUNDUP((J16*0.05+J16),3)),ROUNDUP((J16*0.05+J16),3)) -> 42.525 | L16: =IF(I16=1,"-",IF(AND(I16="",L14="-"),"-",ROUNDUP((J16*0.2)+J16,3))) -> -
A17: 32 | B17: NEW | C17: 8389 | D17: Iron | E17: Unisex - Unisex - Unisex | F17: 35-50 | G17: Color - Colour - Couleur | H17: 10 | I17: 1 | J17: =ROUNDUP('Tarifa 2026'!J18*(1+Instructions!$AA$9),3) -> 43 | K17: =IF(I17=1,(ROUNDUP((J17*0.05+J17),3)),ROUNDUP((J17*0.05+J17),3)) -> 45.15 | L17: =IF(I17=1,"-",IF(AND(I17="",L15="-"),"-",ROUNDUP((J17*0.2)+J17,3))) -> -
... A23: 42 | B23: NEW | C23: 8396 | D23: Basalt | E23: Unisex - Unisex - Unisex | F23: 34-50 | G23: Color - Colour - Couleur | H23: 10 | I23: 1 | J23: =ROUNDUP('Tarifa 2026'!J24*(1+Instructions!$AA$9),3) -> 63 | K23: =IF(I23=1,(ROUNDUP((J23*0.05+J23),3)),ROUNDUP((J23*0.05+J23),3)) -> 66.15 | L23: =IF(I23=1,"-",IF(AND(I23="",L21="-"),"-",ROUNDUP((J23*0.2)+J23,3))) -> -
A24: ALTA VISIBILIDAD · HI-VIZ · HAUTE VISIBILITÉ
A25: 49 | B25: NEW | C25: 9324 | D25: Foran | E25: Unisex - Unisex - Unisex | F25: XS-2XL | G25: Color - Colour - Couleur | H25: 50 | I25: 1 | J25: =ROUNDUP('Tarifa 2026'!J26*(1+Instructions!$AA$9),3) -> 15.9 | K25: =IF(I25=1,(ROUNDUP((J25*0.05+J25),3)),ROUNDUP((J25*0.05+J25),3)) -> 16.695 | L25: =IF(I25=1,"-",IF(AND(I25="",L11="-"),"-",ROUNDUP((J25*0.2)+J25,3))) -> -
E26: Unisex - Unisex - Unisex | F26: 3XL | G26: Color - Colour - Couleur | J26: =ROUNDUP('Tarifa 2026'!J27*(1+Instructions!$AA$9),3) -> 16.7 | K26: =IF(I26=1,(ROUNDUP((J26*0.05+J26),3)),ROUNDUP((J26*0.05+J26),3)) -> 17.535 | L26: =IF(I26=1,"-",IF(AND(I26="",L12="-"),"-",ROUNDUP((J26*0.2)+J26,3))) -> -
A27: 49 | B27: NEW | C27: 9325 | D27: Foran L/S | E27: Unisex - Unisex - Unisex | F27: XS-2XL | G27: Color - Colour - Couleur | H27: 25 | I27: 1 | J27: =ROUNDUP('Tarifa 2026'!J28*(1+Instructions!$AA$9),3) -> 19.9 | K27: =IF(I27=1,(ROUNDUP((J27*0.05+J27),3)),ROUNDUP((J27*0.05+J27),3)) -> 20.895 | L27: =IF(I27=1,"-",IF(AND(I27="",L13="-"),"-",ROUNDUP((J27*0.2)+J27,3))) -> -
E28: Unisex - Unisex - Unisex | F28: 3XL | G28: Color - Colour - Couleur | J28: =ROUNDUP('Tarifa 2026'!J29*(1+Instructions!$AA$9),3) -> 21 | K28: =IF(I28=1,(ROUNDUP((J28*0.05+J28),3)),ROUNDUP((J28*0.05+J28),3)) -> 22.05 | L28: =IF(I28=1,"-",IF(AND(I28="",L14="-"),"-",ROUNDUP((J28*0.2)+J28,3))) -> -
A29: 50 | B29: See photo | C29: 9317 | D29: Tauri | E29: Unisex - Unisex - Unisex | F29: S-2XL | G29: Color - Colour - Couleur | H29: 50 | I29: 1 | J29: =ROUNDUP('Tarifa 2026'!J30*(1+Instructions!$AA$9),3) -> 17.9 | K29: =IF(I29=1,(ROUNDUP((J29*0.05+J29),3)),ROUNDUP((J29*0.05+J29),3)) -> 18.795 | L29: =IF(I29=1,"-",IF(AND(I29="",L27="-"),"-",ROUNDUP((J29*0.2)+J29,3))) -> -
E30: Unisex - Unisex - Unisex | F30: 3XL | G30: Color - Colour - Couleur | J30: =ROUNDUP('Tarifa 2026'!J31*(1+Instructions!$AA$9),3) -> 19.5 | K30: =IF(I30=1,(ROUNDUP((J30*0.05+J30),3)),ROUNDUP((J30*0.05+J30),3)) -> 20.475 | L30: =IF(I30=1,"-",IF(AND(I30="",L29="-"),"-",ROUNDUP((J30*0.2)+J30,3))) -> -
E31: Unisex - Unisex - Unisex | F31: 4XL | G31: Color - Colour - Couleur | J31: =ROUNDUP('Tarifa 2026'!J32*(1+Instructions!$AA$9),3) -> 20 | K31: =IF(I31=1,(ROUNDUP((J31*0.05+J31),3)),ROUNDUP((J31*0.05+J31),3)) -> 21 | L31: =IF(I31=1,"-",IF(AND(I31="",L29="-"),"-",ROUNDUP((J31*0.2)+J31,3))) -> -
A32: 50 | B32: See photo | C32: 9318 | D32: Atrio | E32: Unisex - Unisex - Unisex | F32: S-2XL | G32: Color - Colour - Couleur | H32: 50 | I32: 1 | J32: =ROUNDUP('Tarifa 2026'!J33*(1+Instructions!$AA$9),3) -> 19.9 | K32: =IF(I32=1,(ROUNDUP((J32*0.05+J32),3)),ROUNDUP((J32*0.05+J32),3)) -> 20.895 | L32: =IF(I32=1,"-",IF(AND(I32="",L30="-"),"-",ROUNDUP((J32*0.2)+J32,3))) -> -
E33: Unisex - Unisex - Unisex | F33: 3XL | G33: Color - Colour - Couleur | J33: =ROUNDUP('Tarifa 2026'!J34*(1+Instructions!$AA$9),3) -> 21 | K33: =IF(I33=1,(ROUNDUP((J33*0.05+J33),3)),ROUNDUP((J33*0.05+J33),3)) -> 22.05 | L33: =IF(I33=1,"-",IF(AND(I33="",L31="-"),"-",ROUNDUP((J33*0.2)+J33,3))) -> -
E34: Unisex - Unisex - Unisex | F34: 4XL | G34: Color - Colour - Couleur | J34: =ROUNDUP('Tarifa 2026'!J35*(1+Instructions!$AA$9),3) -> 22 | K34: =IF(I34=1,(ROUNDUP((J34*0.05+J34),3)),ROUNDUP((J34*0.05+J34),3)) -> 23.1 | L34: =IF(I34=1,"-",IF(AND(I34="",L32="-"),"-",ROUNDUP((J34*0.2)+J34,3))) -> -
A35: 51 | B35: See photo | C35: 9319 | D35: Atrio L/S | E35: Unisex - Unisex - Unisex | F35: S-2XL | G35: Color - Colour - Couleur | H35: 50 | I35: 1 | J35: =ROUNDUP('Tarifa 2026'!J36*(1+Instructions!$AA$9),3) -> 25 | K35: =IF(I35=1,(ROUNDUP((J35*0.05+J35),3)),ROUNDUP((J35*0.05+J35),3)) -> 26.25 | L35: =IF(I35=1,"-",IF(AND(I35="",L33="-"),"-",ROUNDUP((J35*0.2)+J35,3))) -> -
E36: Unisex - Unisex - Unisex | F36: 3XL | G36: Color - Colour - Couleur | J36: =ROUNDUP('Tarifa 2026'!J37*(1+Instructions!$AA$9),3) -> 26.3 | K36: =IF(I36=1,(ROUNDUP((J36*0.05+J36),3)),ROUNDUP((J36*0.05+J36),3)) -> 27.615 | L36: =IF(I36=1,"-",IF(AND(I36="",L34="-"),"-",ROUNDUP((J36*0.2)+J36,3))) -> -
E37: Unisex - Unisex - Unisex | F37: 4XL | G37: Color - Colour - Couleur | J37: =ROUNDUP('Tarifa 2026'!J38*(1+Instructions!$AA$9),3) -> 27.6 | K37: =IF(I37=1,(ROUNDUP((J37*0.05+J37),3)),ROUNDUP((J37*0.05+J37),3)) -> 28.98 | L37: =IF(I37=1,"-",IF(AND(I37="",L35="-"),"-",ROUNDUP((J37*0.2)+J37,3))) -> -
A38: 52 | B38: See photo | C38: 9315 | D38: Vega | E38: Unisex - Unisex - Unisex | F38: S-2XL | G38: Color - Colour - Couleur | H38: 50 | I38: 1 | J38: =ROUNDUP('Tarifa 2026'!J39*(1+Instructions!$AA$9),3) -> 13 | K38: =IF(I38=1,(ROUNDUP((J38*0.05+J38),3)),ROUNDUP((J38*0.05+J38),3)) -> 13.65 | L38: =IF(I38=1,"-",IF(AND(I38="",L36="-"),"-",ROUNDUP((J38*0.2)+J38,3))) -> -
E39: Unisex - Unisex - Unisex | F39: 3XL | G39: Color - Colour - Couleur | J39: =ROUNDUP('Tarifa 2026'!J40*(1+Instructions!$AA$9),3) -> 13.8 | K39: =IF(I39=1,(ROUNDUP((J39*0.05+J39),3)),ROUNDUP((J39*0.05+J39),3)) -> 14.49 | L39: =IF(I39=1,"-",IF(AND(I39="",L37="-"),"-",ROUNDUP((J39*0.2)+J39,3))) -> -
E40: Unisex - Unisex - Unisex | F40: 4XL | G40: Color - Colour - Couleur | J40: =ROUNDUP('Tarifa 2026'!J41*(1+Instructions!$AA$9),3) -> 14.5 | K40: =IF(I40=1,(ROUNDUP((J40*0.05+J40),3)),ROUNDUP((J40*0.05+J40),3)) -> 15.225 | L40: =IF(I40=1,"-",IF(AND(I40="",L38="-"),"-",ROUNDUP((J40*0.2)+J40,3))) -> -
A41: 52 | B41: See photo | C41: 9316 | D41: Vega L/S | E41: Unisex - Unisex - Unisex | F41: S-2XL | G41: Color - Colour - Couleur | H41: 25 | I41: 1 | J41: =ROUNDUP('Tarifa 2026'!J42*(1+Instructions!$AA$9),3) -> 17 | K41: =IF(I41=1,(ROUNDUP((J41*0.05+J41),3)),ROUNDUP((J41*0.05+J41),3)) -> 17.85 | L41: =IF(I41=1,"-",IF(AND(I41="",L39="-"),"-",ROUNDUP((J41*0.2)+J41,3))) -> -
E42: Unisex - Unisex - Unisex | F42: 3XL | G42: Color - Colour - Couleur | J42: =ROUNDUP('Tarifa 2026'!J43*(1+Instructions!$AA$9),3) -> 17.9 | K42: =IF(I42=1,(ROUNDUP((J42*0.05+J42),3)),ROUNDUP((J42*0.05+J42),3)) -> 18.795 | L42: =IF(I42=1,"-",IF(AND(I42="",L40="-"),"-",ROUNDUP((J42*0.2)+J42,3))) -> -
E43: Unisex - Unisex - Unisex | F43: 4XL | G43: Color - Colour - Couleur | J43: =ROUNDUP('Tarifa 2026'!J44*(1+Instructions!$AA$9),3) -> 19 | K43: =IF(I43=1,(ROUNDUP((J43*0.05+J43),3)),ROUNDUP((J43*0.05+J43),3)) -> 19.95 | L43: =IF(I43=1,"-",IF(AND(I43="",L41="-"),"-",ROUNDUP((J43*0.2)+J43,3))) -> -
A44: 54 | B44: See photo | C44: 9310 | D44: Delta | E44: Unisex - Unisex - Unisex | F44: S-2XL | G44: Color - Colour - Couleur | H44: 50 | I44: 1 | J44: =ROUNDUP('Tarifa 2026'!J45*(1+Instructions!$AA$9),3) -> 9.3 | K44: =IF(I44=1,(ROUNDUP((J44*0.05+J44),3)),ROUNDUP((J44*0.05+J44),3)) -> 9.765 | L44: =IF(I44=1,"-",IF(AND(I44="",L42="-"),"-",ROUNDUP((J44*0.2)+J44,3))) -> -
E45: Unisex - Unisex - Unisex | F45: 3XL | G45: Color - Colour - Couleur | J45: =ROUNDUP('Tarifa 2026'!J46*(1+Instructions!$AA$9),3) -> 9.8 | K45: =IF(I45=1,(ROUNDUP((J45*0.05+J45),3)),ROUNDUP((J45*0.05+J45),3)) -> 10.29 | L45: =IF(I45=1,"-",IF(AND(I45="",L43="-"),"-",ROUNDUP((J45*0.2)+J45,3))) -> -
...
